<mujoco model="allegro_right">
  <compiler angle="radian"/>
  <asset>
    <mesh name="base_link" file="../meshes/visual/base_link.obj"/>
    <mesh name="link_0.0" file="../meshes/visual/link_0.0.obj"/>
    <mesh name="link_1.0" file="../meshes/visual/link_1.0.obj"/>
    <mesh name="link_2.0" file="../meshes/visual/link_2.0.obj"/>
    <mesh name="link_3.0" file="../meshes/visual/link_3.0.obj"/>
    <mesh name="longer_finger_tip" file="meshes/collision/longer_finger_tip.obj" scale="0.001 0.001 0.001"/>
    <mesh name="link_12.0_right" file="../meshes/visual/link_12.0_right.obj"/>
    <mesh name="link_13.0" file="../meshes/visual/link_13.0.obj"/>
    <mesh name="link_14.0" file="../meshes/visual/link_14.0.obj"/>
    <mesh name="link_15.0" file="../meshes/visual/link_15.0.obj"/>
  </asset>
  <worldbody>
    <body name="base_link" euler="0 -1.57 0">
      <inertial pos="0 0 0" mass="0.4154" diaginertia="0.0001 0.0001 0.0001"/>
      <geom type="mesh" contype="0" conaffinity="0" group="1" density="0" mesh="base_link"/>
      <geom size="0.0207 0.056 0.0224" pos="-0.009 0 -0.023" group="2" type="box"/>
      <geom size="0.0207 0.0269 0.0214" pos="-0.009 -0.0253 -0.0667" group="2" type="box"/>
      <geom size="0.0207 0.036 0.0065" pos="-0.0093 -0.00557 -0.08874" group="2" type="box"/>
      <body name="palm" pos="0 0 -0.065">
        <body name="wrist" pos="0 0 -0.03"/>
      </body>
      <body name="link_0.0" pos="0 0.0435 -0.001542" quat="0.999048 -0.0436194 0 0">
        <inertial pos="0 0 0" quat="0.707107 0.707107 0 0" mass="0.0119" diaginertia="1.01667e-06 1.01667e-06 6.47677e-07"/>
        <joint name="joint_0.0" pos="0 0 0" axis="0 0 1" limited="true" range="-0.47 0.47"/>
        <geom type="mesh" contype="0" conaffinity="0" group="1" density="0" mesh="link_0.0"/>
        <geom size="0.0098 0.01375 0.0082" pos="0 0 0.0082" group="2" type="box"/>
        <body name="link_1.0" pos="0 0 0.0164">
          <inertial pos="0 0 0" quat="0.702596 0.559386 -0.178354 0.402039" mass="0.065" diaginertia="6.12799e-05 6.12799e-05 6.12799e-05"/>
          <joint name="joint_1.0" pos="0 0 0" axis="0 1 0" limited="true" range="-0.196 1.61"/>
          <geom type="mesh" contype="0" conaffinity="0" group="1" density="0" mesh="link_1.0"/>
          <geom size="0.0098 0.01375 0.027" pos="0 0 0.027" group="2" type="box"/>
          <body name="link_1.0_fsr" pos="0 0 0.02">
            <geom size="0.0015 0.0114 0.0084" pos="0.0108 0 0" type="box" contype="0" conaffinity="0" group="1" density="0" rgba="1 0 0 1"/>
            <geom size="0.0015 0.0114 0.0084" pos="0.0108 0 0" group="2" type="box" rgba="1 0 0 1"/>
          </body>
          <body name="link_2.0" pos="0 0 0.054">
            <inertial pos="0 0 0" quat="0.719796 0.528175 -0.157463 0.422055" mass="0.0355" diaginertia="2.20969e-05 2.20969e-05 2.20969e-05"/>
            <joint name="joint_2.0" pos="0 0 0" axis="0 1 0" limited="true" range="-0.174 1.709"/>
            <geom type="mesh" contype="0" conaffinity="0" group="1" density="0" mesh="link_2.0"/>
            <geom size="0.0098 0.01375 0.0192" pos="0 0 0.0192" group="2" type="box"/>
            <body name="link_2.0_fsr" pos="0 0 0.02">
              <geom size="0.0015 0.0114 0.0084" pos="0.0108 0 0" type="box" contype="0" conaffinity="0" group="1" density="0" rgba="1 0 0 1"/>
              <geom size="0.0015 0.0114 0.0084" pos="0.0108 0 0" group="2" type="box" rgba="1 0 0 1"/>
            </body>
            <body name="link_3.0" pos="0 0 0.0384">
              <inertial pos="0 0 0.01335" quat="0.5 0.5 0.5 0.5" mass="0.02" diaginertia="2e-05 2e-05 1e-05"/>
              <joint name="joint_3.0" pos="0 0 0" axis="0 1 0" limited="true" range="-0.227 1.618"/>
              <geom type="mesh" contype="0" conaffinity="0" group="1" density="0" mesh="link_3.0"/>
              <geom size="0.0098 0.01345 0.011" pos="0 0 0.0047" group="2" type="box"/>
              <body name="link_3.0_tip" pos="0 0 0.06">
                <geom pos="0 0 -0.02" quat="0.707107 0 0 0.707106" type="mesh" contype="0" conaffinity="0" group="1" density="0" mesh="longer_finger_tip"/>
                <geom pos="0 0 -0.02" quat="0.707107 0 0 0.707106" type="mesh" mesh="longer_finger_tip" group="2"/>
                <body name="link_3.0_tip_fsr" pos="-0.005 0 -0.015">
                  <geom size="0.0015 0.0114 0.0084" pos="0.0108 0 0" type="box" contype="0" conaffinity="0" group="1" density="0" rgba="1 0 0 1"/>
                  <geom size="0.0015 0.0114 0.0084" pos="0.0108 0 0" group="2" type="box" rgba="1 0 0 1"/>
                </body>
              </body>
            </body>
          </body>
        </body>
      </body>
      <body name="link_4.0" pos="0 0 0.0007">
        <inertial pos="0 0 0" quat="0.5 0.5 -0.5 0.5" mass="0.005" diaginertia="6.125e-05 5.1458e-05 5.1458e-05"/>
        <joint name="joint_4.0" pos="0 0 0" axis="0 0 1" limited="true" range="-0.47 0.47"/>
        <geom type="mesh" contype="0" conaffinity="0" group="1" density="0" mesh="link_0.0"/>
        <geom size="0.0098 0.01375 0.0082" pos="0 0 0.0082" group="2" type="box"/>
        <body name="link_5.0" pos="0 0 0.0164">
          <inertial pos="0 0 0" quat="0.702596 0.559386 -0.178354 0.402039" mass="0.065" diaginertia="6.12799e-05 6.12799e-05 6.12799e-05"/>
          <joint name="joint_5.0" pos="0 0 0" axis="0 1 0" limited="true" range="-0.196 1.61"/>
          <geom type="mesh" contype="0" conaffinity="0" group="1" density="0" mesh="link_1.0"/>
          <geom size="0.0098 0.01375 0.027" pos="0 0 0.027" group="2" type="box"/>
          <body name="link_5.0_fsr" pos="0 0 0.02">
            <geom size="0.0015 0.0114 0.0084" pos="0.0108 0 0" type="box" contype="0" conaffinity="0" group="1" density="0" rgba="1 0 0 1"/>
            <geom size="0.0015 0.0114 0.0084" pos="0.0108 0 0" group="2" type="box" rgba="1 0 0 1"/>
          </body>
          <body name="link_6.0" pos="0 0 0.054">
            <inertial pos="0 0 0" quat="0.719796 0.528175 -0.157463 0.422055" mass="0.0355" diaginertia="2.20969e-05 2.20969e-05 2.20969e-05"/>
            <joint name="joint_6.0" pos="0 0 0" axis="0 1 0" limited="true" range="-0.174 1.709"/>
            <geom type="mesh" contype="0" conaffinity="0" group="1" density="0" mesh="link_2.0"/>
            <geom size="0.0098 0.01375 0.0192" pos="0 0 0.0192" group="2" type="box"/>
            <body name="link_6.0_fsr" pos="0 0 0.02">
              <geom size="0.0015 0.0114 0.0084" pos="0.0108 0 0" type="box" contype="0" conaffinity="0" group="1" density="0" rgba="1 0 0 1"/>
              <geom size="0.0015 0.0114 0.0084" pos="0.0108 0 0" group="2" type="box" rgba="1 0 0 1"/>
            </body>
            <body name="link_7.0" pos="0 0 0.0384">
              <inertial pos="0 0 0" quat="0.714142 0.538398 -0.162448 0.416821" mass="0.0388" diaginertia="2.68646e-05 2.68646e-05 2.68646e-05"/>
              <joint name="joint_7.0" pos="0 0 0" axis="0 1 0" limited="true" range="-0.227 1.618"/>
              <geom type="mesh" contype="0" conaffinity="0" group="1" density="0" mesh="link_3.0"/>
              <geom size="0.0098 0.01345 0.011" pos="0 0 0.0047" group="2" type="box"/>
              <body name="link_7.0_tip" pos="0 0 0.06">
                <geom pos="0 0 -0.02" quat="0.707107 0 0 0.707106" type="mesh" contype="0" conaffinity="0" group="1" density="0" mesh="longer_finger_tip"/>
                <geom pos="0 0 -0.02" quat="0.707107 0 0 0.707106" type="mesh" mesh="longer_finger_tip" group="2"/>
                <body name="link_7.0_tip_fsr" pos="-0.005 0 -0.015">
                  <geom size="0.0015 0.0114 0.0084" pos="0.0108 0 0" type="box" contype="0" conaffinity="0" group="1" density="0" rgba="1 0 0 1"/>
                  <geom size="0.0015 0.0114 0.0084" pos="0.0108 0 0" group="2" type="box" rgba="1 0 0 1"/>
                </body>
              </body>
            </body>
          </body>
        </body>
      </body>
      <body name="link_8.0" pos="0 -0.0435 -0.001542" quat="0.999048 0.0436194 0 0">
        <inertial pos="0 0 0" quat="0.5 0.5 -0.5 0.5" mass="0.005" diaginertia="6.125e-05 5.1458e-05 5.1458e-05"/>
        <joint name="joint_8.0" pos="0 0 0" axis="0 0 1" limited="true" range="-0.47 0.47"/>
        <geom type="mesh" contype="0" conaffinity="0" group="1" density="0" mesh="link_0.0"/>
        <geom size="0.0098 0.01375 0.0082" pos="0 0 0.0082" group="2" type="box"/>
        <body name="link_9.0" pos="0 0 0.0164">
          <inertial pos="0 0 0" quat="0.702596 0.559386 -0.178354 0.402039" mass="0.065" diaginertia="6.12799e-05 6.12799e-05 6.12799e-05"/>
          <joint name="joint_9.0" pos="0 0 0" axis="0 1 0" limited="true" range="-0.196 1.61"/>
          <geom type="mesh" contype="0" conaffinity="0" group="1" density="0" mesh="link_1.0"/>
          <geom size="0.0098 0.01375 0.027" pos="0 0 0.027" group="2" type="box"/>
          <body name="link_9.0_fsr" pos="0 0 0.02">
            <geom size="0.0015 0.0114 0.0084" pos="0.0108 0 0" type="box" contype="0" conaffinity="0" group="1" density="0" rgba="1 0 0 1"/>
            <geom size="0.0015 0.0114 0.0084" pos="0.0108 0 0" group="2" type="box" rgba="1 0 0 1"/>
          </body>
          <body name="link_10.0" pos="0 0 0.054">
            <inertial pos="0 0 0" quat="0.719796 0.528175 -0.157463 0.422055" mass="0.0355" diaginertia="2.20969e-05 2.20969e-05 2.20969e-05"/>
            <joint name="joint_10.0" pos="0 0 0" axis="0 1 0" limited="true" range="-0.174 1.709"/>
            <geom type="mesh" contype="0" conaffinity="0" group="1" density="0" mesh="link_2.0"/>
            <geom size="0.0098 0.01375 0.0192" pos="0 0 0.0192" group="2" type="box"/>
            <body name="link_10.0_fsr" pos="0 0 0.02">
              <geom size="0.0015 0.0114 0.0084" pos="0.0108 0 0" type="box" contype="0" conaffinity="0" group="1" density="0" rgba="1 0 0 1"/>
              <geom size="0.0015 0.0114 0.0084" pos="0.0108 0 0" group="2" type="box" rgba="1 0 0 1"/>
            </body>
            <body name="link_11.0" pos="0 0 0.0384">
              <inertial pos="0 0 0" quat="0.760448 0.456478 -0.161222 0.432844" mass="0.0096" diaginertia="4.3506e-06 4.3506e-06 4.3506e-06"/>
              <joint name="joint_11.0" pos="0 0 0" axis="0 1 0" limited="true" range="-0.227 1.618"/>
              <geom type="mesh" contype="0" conaffinity="0" group="1" density="0" mesh="link_3.0"/>
              <geom size="0.0098 0.01345 0.011" pos="0 0 0.0047" group="2" type="box"/>
              <body name="link_11.0_tip" pos="0 0 0.06">
                <geom pos="0 0 -0.02" quat="0.707107 0 0 0.707106" type="mesh" contype="0" conaffinity="0" group="1" density="0" mesh="longer_finger_tip"/>
                <geom pos="0 0 -0.02" quat="0.707107 0 0 0.707106" type="mesh" mesh="longer_finger_tip" group="2"/>
                <body name="link_11.0_tip_fsr" pos="-0.005 0 -0.015">
                  <geom size="0.0015 0.0114 0.0084" pos="0.0108 0 0" type="box" contype="0" conaffinity="0" group="1" density="0" rgba="1 0 0 1"/>
                  <geom size="0.0015 0.0114 0.0084" pos="0.0108 0 0" group="2" type="box" rgba="1 0 0 1"/>
                </body>
              </body>
            </body>
          </body>
        </body>
      </body>
      <body name="link_12.0" pos="-0.0182 0.019333 -0.045987" quat="0.477714 -0.521334 -0.521334 -0.477714">
        <inertial pos="0 0 0" quat="0.692635 0.569362 -0.07143 0.437013" mass="0.0176" diaginertia="1.73852e-05 1.73852e-05 1.73852e-05"/>
        <joint name="joint_12.0" pos="0 0 0" axis="-1 0 0" limited="true" range="0.263 1.396"/>
        <geom type="mesh" contype="0" conaffinity="0" group="1" density="0" mesh="link_12.0_right"/>
        <geom size="0.0179 0.017 0.02275" pos="-0.0179 0.009 0.0145" group="2" type="box"/>
        <body name="link_13.0" pos="-0.027 0.005 0.0399">
          <inertial pos="0 0 0" quat="-0.0269589 0.880876 0.334036 0.334292" mass="0.0119" diaginertia="4.33621e-06 4.33621e-06 4.33621e-06"/>
          <joint name="joint_13.0" pos="0 0 0" axis="0 0 1" limited="true" range="-0.105 1.163"/>
          <geom type="mesh" contype="0" conaffinity="0" group="1" density="0" mesh="link_13.0"/>
          <geom size="0.0098 0.01375 0.00885" pos="0 0 0.00885" group="2" type="box"/>
          <body name="link_14.0" pos="0 0 0.0177">
            <inertial pos="0 0 0" quat="0.70472 0.55555 -0.174905 0.405146" mass="0.038" diaginertia="3.35111e-05 3.35111e-05 3.35111e-05"/>
            <joint name="joint_14.0" pos="0 0 0" axis="0 1 0" limited="true" range="-0.189 1.644"/>
            <geom type="mesh" contype="0" conaffinity="0" group="1" density="0" mesh="link_14.0"/>
            <geom size="0.0098 0.01375 0.0257" pos="0 0 0.0257" group="2" type="box"/>
            <body name="link_14.0_fsr" pos="0 0 0.02">
              <geom size="0.0015 0.0114 0.0084" pos="0.0108 0 0" type="box" contype="0" conaffinity="0" group="1" density="0" rgba="1 0 0 1"/>
              <geom size="0.0015 0.0114 0.0084" pos="0.0108 0 0" group="2" type="box" rgba="1 0 0 1"/>
            </body>
            <body name="link_15.0" pos="0 0 0.0514">
              <inertial pos="0 0 0" quat="0.714142 0.538398 -0.162448 0.416821" mass="0.0388" diaginertia="2.68646e-05 2.68646e-05 2.68646e-05"/>
              <joint name="joint_15.0" pos="0 0 0" axis="0 1 0" limited="true" range="-0.162 1.719"/>
              <geom type="mesh" contype="0" conaffinity="0" group="1" density="0" mesh="link_15.0"/>
              <geom size="0.0098 0.01345 0.02" pos="0 0 0.01125" group="2" type="box"/>
              <body name="link_15.0_fsr" pos="0 0 0.02">
                <geom size="0.0015 0.0114 0.0084" pos="0.0108 0 0" type="box" contype="0" conaffinity="0" group="1" density="0" rgba="1 0 0 1"/>
                <geom size="0.0015 0.0114 0.0084" pos="0.0108 0 0" group="2" type="box" rgba="1 0 0 1"/>
              </body>
              <body name="link_15.0_tip" pos="0 0 0.075">
                <geom pos="0 0 -0.02" quat="0.707107 0 0 0.707106" type="mesh" contype="0" conaffinity="0" group="1" density="0" mesh="longer_finger_tip"/>
                <geom pos="0 0 -0.02" quat="0.707107 0 0 0.707106" type="mesh" mesh="longer_finger_tip" group="2"/>
                <body name="link_15.0_tip_fsr" pos="-0.005 0 -0.015">
                  <geom size="0.0015 0.0114 0.0084" pos="0.0108 0 0" type="box" contype="0" conaffinity="0" group="1" density="0" rgba="1 0 0 1"/>
                  <geom size="0.0015 0.0114 0.0084" pos="0.0108 0 0" group="2" type="box" rgba="1 0 0 1"/>
                </body>
              </body>
            </body>
          </body>
        </body>
      </body>
      <body name="link_base_fsr" pos="0.002 -0.035 -0.065" quat="0.998988 -0.0449848 0 0">
        <geom size="0.0015 0.0114 0.0084" pos="0.0108 0 0" type="box" contype="0" conaffinity="0" group="1" density="0" rgba="1 0 0 1"/>
        <geom size="0.0015 0.0114 0.0084" pos="0.0108 0 0" group="2" type="box" rgba="1 0 0 1"/>
      </body>
      <body name="link_8.0_fsr" pos="0.001 -0.041 -0.015" quat="0.998988 -0.0449848 0 0">
        <geom size="0.0015 0.0114 0.0084" pos="0.0108 0 0" type="box" contype="0" conaffinity="0" group="1" density="0" rgba="1 0 0 1"/>
        <geom size="0.0015 0.0114 0.0084" pos="0.0108 0 0" group="2" type="box" rgba="1 0 0 1"/>
      </body>
      <body name="link_4.0_fsr" pos="0.001 0 -0.013">
        <geom size="0.0015 0.0114 0.0084" pos="0.0108 0 0" type="box" contype="0" conaffinity="0" group="1" density="0" rgba="1 0 0 1"/>
        <geom size="0.0015 0.0114 0.0084" pos="0.0108 0 0" group="2" type="box" rgba="1 0 0 1"/>
      </body>
      <body name="link_0.0_fsr" pos="0.001 0.041 -0.015" quat="0.998988 0.0449848 0 0">
        <geom size="0.0015 0.0114 0.0084" pos="0.0108 0 0" type="box" contype="0" conaffinity="0" group="1" density="0" rgba="1 0 0 1"/>
        <geom size="0.0015 0.0114 0.0084" pos="0.0108 0 0" group="2" type="box" rgba="1 0 0 1"/>
      </body>
    </body>
  </worldbody>
</mujoco>
